<?xml version="1.0"?>
<robot xmlns:xacro="http://www.ros.org/wiki/xacro" name="tri_bot">

  <!-- Inertia formulas -->
  <xacro:macro name="box_inertia" params="m w h d xyz rpy">
    <inertial>
      <origin xyz="${xyz}" rpy="${rpy}"/>
      <mass value="${m}"/>
      <inertia ixx="${(m/12) * (h*h + d*d)}" ixy="0.0" ixz="0.0"
               iyy="${(m/12) * (w*w + d*d)}" iyz="0.0"
               izz="${(m/12) * (w*w + h*h)}"/>
    </inertial>
  </xacro:macro>

  <xacro:macro name="cylinder_inertia" params="m r h xyz rpy">
    <inertial>
      <origin xyz="${xyz}" rpy="${rpy}"/>
      <mass value="${m}"/>
      <inertia ixx="${(m/12) * (3*r*r + h*h)}" ixy = "0.0" ixz = "0.0"
               iyy="${(m/12) * (3*r*r + h*h)}" iyz = "0.0"
               izz="${(m/2) * (r*r)}"/>
    </inertial>
  </xacro:macro>

  <xacro:macro name="sphere_inertia" params="m r xyz rpy">
    <inertial>
      <origin xyz="${xyz}" rpy="${rpy}"/>
      <mass value="${m}"/>
      <inertia ixx="${(2/5) * m * (r*r)}" ixy="0.0" ixz="0.0"
               iyy="${(2/5) * m * (r*r)}" iyz="0.0"
               izz="${(2/5) * m * (r*r)}"/>
    </inertial>
  </xacro:macro>

  <!-- All the values below are approxiamated -->
  <!-- The value indicates the length in meter -->
  <xacro:property name="body_length" value="0.16" />
  <xacro:property name="body_width" value="0.075" />
  <xacro:property name="single_wing_span" value="0.25" />
  <xacro:property name="tail_length" value="0.2" />
  <xacro:property name="nose_length" value="0.08" />

  <xacro:property name="zoom_cam_size" value="0.019" />
  <xacro:property name="night_cam_size_x" value="0.02" />
  <xacro:property name="night_cam_size_y" value="0.02" />
  <xacro:property name="night_cam_size_z" value="0.02854" />
  <xacro:property name="cam_separation" value="0.04" />

  <material name="blue">
    <color rgba="0 0 0.8 1"/>
  </material>
  <material name="white">
    <color rgba="1 1 1 1"/>
  </material>
  <material name="red">
    <color rgba="0.8 0 0 1"/>
  </material>
  <material name="black">
    <color rgba="0.1 0.1 0.1 1"/>
  </material>

  <link name="base_link">
    <visual>
      <geometry>
        <box size="${body_length} ${body_width} ${body_width}"/>
      </geometry>
      <material name="white"/>
    </visual>
    <collision>
      <geometry>
        <box size="${body_length} ${body_width} ${body_width}"/>
      </geometry>
    </collision>
    <xacro:box_inertia m="3" w="${body_length}" h="${body_width}" d="${body_width}" xyz="0 0 0" rpy="0 0 0"/>
  </link>

  <link name="nose_link">
    <visual>
      <geometry>
        <cylinder radius="${body_width/2}" length="${nose_length}"/>
      </geometry>
      <origin xyz="${nose_length/2} 0 0" rpy="0 1.57 0"/>
      <material name="blue"/>
    </visual>
    <collision>
      <geometry>
        <cylinder radius="${body_width/2}" length="${nose_length}"/>
      </geometry>
      <origin xyz="${nose_length/2} 0 0" rpy="0 1.57 0"/>
    </collision>
    <xacro:cylinder_inertia m="0.1" r="${body_width/2}" h="${nose_length}" xyz="${nose_length/2} 0 0" rpy="0 1.57 0"/>
  </link>

  <joint name="nose_joint" type="fixed">
    <parent link="base_link"/>
    <child link="nose_link"/>
    <origin xyz="${body_length/2} 0 0"/>
  </joint>

<link name="camera_night_link">
    <visual>
      <geometry>
        <box size="${night_cam_size_x} ${night_cam_size_y} ${night_cam_size_z}"/>
      </geometry>
      <material name="black"/>
    </visual>
    <xacro:box_inertia m="0.01" w="${night_cam_size_x}" h="${night_cam_size_y}" d="${night_cam_size_z}" xyz="0 0 0" rpy="0 0 0"/>
  </link>

  <joint name="camera_night_joint" type="fixed">
    <parent link="nose_link"/>
    <child link="camera_night_link"/>
    <origin xyz="${nose_length*0.8} ${cam_separation/2} 0" rpy="0 0 0"/>
    <xacro:cylinder_inertia m="0.01" r="${zoom_cam_size/2}" h="${zoom_cam_size*1.5}" xyz="0 0 0" rpy="0 1.57 0"/>
  </joint>
  
  <link name="camera_zoom_link">
    <visual>
      <geometry>
        <cylinder radius="${zoom_cam_size/2}" length="${zoom_cam_size*1.5}"/>
      </geometry>
      <origin xyz="0 0 0" rpy="0 1.57 0"/>
      <material name="black"/>
    </visual>
  </link>

  <joint name="camera_zoom_joint" type="fixed">
    <parent link="nose_link"/>
    <child link="camera_zoom_link"/>
    <origin xyz="${nose_length*0.8} -${cam_separation/2} 0" rpy="0 0 0"/>
  </joint>

  <!-- ROS 2 and cameras use 2 different coordinate systems -->
  <!-- The 2 optical frames uniform the standard to the one that ROS 2 uses -->
  <link name="camera_night_optical_frame"/>
  <joint name="camera_night_optical_joint" type="fixed">
    <parent link="camera_night_link"/>
    <child link="camera_night_optical_frame"/>
    <origin xyz="0 0 0" rpy="-1.57 0 -1.57"/>
  </joint>

  <link name="camera_zoom_optical_frame"/>
  <joint name="camera_zoom_optical_joint" type="fixed">
    <parent link="camera_zoom_link"/>
    <child link="camera_zoom_optical_frame"/>
    <origin xyz="0 0 0" rpy="-1.57 0 -1.57"/>
  </joint>

  <link name="left_wing">
    <visual>
      <geometry>
        <box size="0.1 ${single_wing_span} 0.02"/>
      </geometry>
      <origin xyz="0 ${single_wing_span/2} 0" rpy="0 0 0"/>
      <material name="blue"/>
    </visual>
    <xacro:box_inertia m="0.05" w="0.1" h="${single_wing_span}" d="0.02" xyz="0 ${single_wing_span/2} 0" rpy="0 0 0"/>
  </link>

  <joint name="left_wing_fold_joint" type="revolute">
    <parent link="base_link"/>
    <child link="left_wing"/>
    <origin xyz="0.05 ${body_width/2} 0"/>
    <axis xyz="1 0 0"/> <limit lower="-1.57" upper="0" effort="10" velocity="1"/>
  </joint>

  <link name="right_wing">
    <visual>
      <geometry>
        <box size="0.1 ${single_wing_span} 0.02"/>
      </geometry>
      <origin xyz="0 -${single_wing_span/2} 0" rpy="0 0 0"/>
      <material name="blue"/>
    </visual>
    <xacro:box_inertia m="0.05" w="0.1" h="${single_wing_span}" d="0.02" xyz="0 -${single_wing_span/2} 0" rpy="0 0 0"/>
  </link>

  <joint name="right_wing_fold_joint" type="revolute">
    <parent link="base_link"/>
    <child link="right_wing"/>
    <origin xyz="0.05 -${body_width/2} 0"/>
    <axis xyz="1 0 0"/> <limit lower="0" upper="1.57" effort="10" velocity="1"/>
  </joint>

  <link name="tail_mount">
    <visual>
      <geometry>
        <cylinder length="${tail_length}" radius="0.05"/>
      </geometry>
      <origin xyz="-${tail_length/2} 0 0" rpy="0 1.57 0"/>
      <material name="red"/>
    </visual>
    <xacro:cylinder_inertia m="0.05" r="0.05" h="${tail_length}" xyz="-${tail_length/2} 0 0" rpy="0 1.57 0"/>
  </link>

  <joint name="tail_mount_joint" type="fixed">
    <parent link="base_link"/>
    <child link="tail_mount"/>
    <origin xyz="-${body_length/2} 0 0"/>
  </joint>

  <link name="nozzle">
    <visual>
      <geometry>
        <sphere radius="0.06"/>
      </geometry>
      <material name="blue"/>
    </visual>
    <xacro:sphere_inertia m="0.05" r="0.06" xyz="0 0 0" rpy="0 0 0"/>
  </link>

  <joint name="tvc_pitch_joint" type="revolute">
    <parent link="tail_mount"/>
    <child link="nozzle"/>
    <origin xyz="-${tail_length} 0 0"/>
    <axis xyz="0 1 0"/> <limit lower="-0.5" upper="0.5" effort="10" velocity="5"/>
  </joint>

</robot>